<?xml version="1.0" encoding="utf-8"?>
<!-- This URDF was automatically created by SolidWorks to URDF Exporter! Originally created by Stephen Brawner (brawner@gmail.com) 
     Commit Version: 1.6.0-4-g7f85cfe  Build Version: 1.6.7995.38578
     For more information, please see http://wiki.ros.org/sw_urdf_exporter -->
<robot
  name="ensamble_piezas_proyecto">
  <link
    name="base_link">
    <inertial>
      <origin
        xyz="3.5735E-16 0 0.095947"
        rpy="0 0 0" />
      <mass
        value="44.254" />
      <inertia
        ixx="0.2479"
        ixy="-4.8572E-17"
        ixz="-3.7943E-16"
        iyy="0.2479"
        iyz="6.0738E-17"
        izz="0.2121" />
    </inertial>
    <visual>
      <origin
        xyz="0 0 0"
        rpy="0 0 0" />
      <geometry>
        <mesh
          filename="package://ensamble_piezas_proyecto/meshes/base_link.STL" />
      </geometry>
      <material
        name="">
        <color
          rgba="0.52941 0.54902 0.54902 1" />
      </material>
    </visual>
    <collision>
      <origin
        xyz="0 0 0"
        rpy="0 0 0" />
      <geometry>
        <mesh
          filename="package://ensamble_piezas_proyecto/meshes/base_link.STL" />
      </geometry>
    </collision>
  </link>
  <link
    name="Link_1">
    <inertial>
      <origin
        xyz="-0.039302 1.3878E-16 -0.087462"
        rpy="0 0 0" />
      <mass
        value="5.9425" />
      <inertia
        ixx="0.048806"
        ixy="5.8113E-17"
        ixz="0.0077232"
        iyy="0.044867"
        iyz="6.0929E-17"
        izz="0.0629" />
    </inertial>
    <visual>
      <origin
        xyz="0 0 0"
        rpy="0 0 0" />
      <geometry>
        <mesh
          filename="package://ensamble_piezas_proyecto/meshes/Link_1.STL" />
      </geometry>
      <material
        name="">
        <color
          rgba="0.52941 0.54902 0.54902 1" />
      </material>
    </visual>
    <collision>
      <origin
        xyz="0 0 0"
        rpy="0 0 0" />
      <geometry>
        <mesh
          filename="package://ensamble_piezas_proyecto/meshes/Link_1.STL" />
      </geometry>
    </collision>
  </link>
  <joint
    name="joint_1"
    type="revolute">
    <origin
      xyz="0 0 0.362"
      rpy="0 0 0" />
    <parent
      link="base_link" />
    <child
      link="Link_1" />
    <axis
      xyz="0 1 0" />
    <limit
      lower="0"
      upper="1.5708"
      effort="10"
      velocity="2" />
  </joint>
  <link
    name="Link_2">
    <inertial>
      <origin
        xyz="-0.0096234 2.498E-16 0.078698"
        rpy="0 0 0" />
      <mass
        value="5.929" />
      <inertia
        ixx="0.020416"
        ixy="0"
        ixz="2.0444E-17"
        iyy="0.014952"
        iyz="6.053E-18"
        izz="0.007624" />
    </inertial>
    <visual>
      <origin
        xyz="0 0 0"
        rpy="0 0 0" />
      <geometry>
        <mesh
          filename="package://ensamble_piezas_proyecto/meshes/Link_2.STL" />
      </geometry>
      <material
        name="">
        <color
          rgba="0.52941 0.54902 0.54902 1" />
      </material>
    </visual>
    <collision>
      <origin
        xyz="0 0 0"
        rpy="0 0 0" />
      <geometry>
        <mesh
          filename="package://ensamble_piezas_proyecto/meshes/Link_2.STL" />
      </geometry>
    </collision>
  </link>
  <joint
    name="joint_2"
    type="revolute">
    <origin
      xyz="0 0 0"
      rpy="0 0 0" />
    <parent
      link="Link_1" />
    <child
      link="Link_2" />
    <axis
      xyz="0 1 0" />
    <limit
      lower="0"
      upper="1.5708"
      effort="10"
      velocity="2" />
  </joint>
  <link
    name="Link_3">
    <inertial>
      <origin
        xyz="-0.0066731 -2.2204E-16 0.073206"
        rpy="0 0 0" />
      <mass
        value="4.8479" />
      <inertia
        ixx="0.016471"
        ixy="4.3368E-19"
        ixz="2.2296E-17"
        iyy="0.011735"
        iyz="-2.1354E-19"
        izz="0.0062325" />
    </inertial>
    <visual>
      <origin
        xyz="0 0 0"
        rpy="0 0 0" />
      <geometry>
        <mesh
          filename="package://ensamble_piezas_proyecto/meshes/Link_3.STL" />
      </geometry>
      <material
        name="">
        <color
          rgba="0.52941 0.54902 0.54902 1" />
      </material>
    </visual>
    <collision>
      <origin
        xyz="0 0 0"
        rpy="0 0 0" />
      <geometry>
        <mesh
          filename="package://ensamble_piezas_proyecto/meshes/Link_3.STL" />
      </geometry>
    </collision>
  </link>
  <joint
    name="joint_3"
    type="revolute">
    <origin
      xyz="0 0 0.22"
      rpy="0 0 0" />
    <parent
      link="Link_2" />
    <child
      link="Link_3" />
    <axis
      xyz="0 1 0" />
    <limit
      lower="0"
      upper="1.5708"
      effort="10"
      velocity="2" />
  </joint>
  <link
    name="Link_4">
    <inertial>
      <origin
        xyz="6.4382E-12 9.5232E-11 -0.006005"
        rpy="0 0 0" />
      <mass
        value="2.1577" />
      <inertia
        ixx="0.00094682"
        ixy="-3.9213E-12"
        ixz="6.6287E-12"
        iyy="0.0009525"
        iyz="-5.2426E-13"
        izz="0.00047051" />
    </inertial>
    <visual>
      <origin
        xyz="0 0 0"
        rpy="0 0 0" />
      <geometry>
        <mesh
          filename="package://ensamble_piezas_proyecto/meshes/Link_4.STL" />
      </geometry>
      <material
        name="">
        <color
          rgba="0.52941 0.54902 0.54902 1" />
      </material>
    </visual>
    <collision>
      <origin
        xyz="0 0 0"
        rpy="0 0 0" />
      <geometry>
        <mesh
          filename="package://ensamble_piezas_proyecto/meshes/Link_4.STL" />
      </geometry>
    </collision>
  </link>
  <joint
    name="joint_4"
    type="revolute">
    <origin
      xyz="0 0 0.22"
      rpy="0 0 0" />
    <parent
      link="Link_3" />
    <child
      link="Link_4" />
    <axis
      xyz="0 1 0" />
    <limit
      lower="0"
      upper="1.5708"
      effort="10"
      velocity="2" />
  </joint>
  <link
    name="Link_5">
    <inertial>
      <origin
        xyz="8.1466E-05 7.3019E-05 0.047915"
        rpy="0 0 0" />
      <mass
        value="0.68289" />
      <inertia
        ixx="0.0002537"
        ixy="-1.2367E-19"
        ixz="3.3326E-20"
        iyy="0.00013449"
        iyz="-1.4444E-07"
        izz="0.00019153" />
    </inertial>
    <visual>
      <origin
        xyz="0 0 0"
        rpy="0 0 0" />
      <geometry>
        <mesh
          filename="package://ensamble_piezas_proyecto/meshes/Link_5.STL" />
      </geometry>
      <material
        name="">
        <color
          rgba="0.52941 0.54902 0.54902 1" />
      </material>
    </visual>
    <collision>
      <origin
        xyz="0 0 0"
        rpy="0 0 0" />
      <geometry>
        <mesh
          filename="package://ensamble_piezas_proyecto/meshes/Link_5.STL" />
      </geometry>
    </collision>
  </link>
  <joint
    name="joint_5"
    type="revolute">
    <origin
      xyz="0 0 0.039223"
      rpy="0 0 0" />
    <parent
      link="Link_4" />
    <child
      link="Link_5" />
    <axis
      xyz="0 0 -1" />
    <limit
      lower="0"
      upper="1.5708"
      effort="10"
      velocity="2" />
  </joint>
</robot>